Workbook
Name StartingBalance: #REF!

Sheet 07-26
B1: Change or add categories by updating the Expenses and Income tables in the SumJuly sheet.
B2: Expenses | G2: Income
M3: Monthly Budget
B4: Date | C4: Amount | D4: Description | E4: Category | G4: Date | H4: Amount | I4: Description | J4: Category
B5: 46204 | C5: 794 | D5: Broadband & TV | E5: Utilities | G5: 46204 | H5: 319000 | I5: Salary | J5: Paycheck
B6: 46204 | C6: 10000 | D6: PO | E6: Savings-Mandatory
B7: 46204 | C7: 16000 | D7: RD | E7: Savings-Mandatory
B8: 46204 | C8: 279 | D8: OTT | E8: Entertainment
B9: 46204 | C9: 0 | D9: Maintenance | E9: Utilities
B10: 46204 | C10: 9600 | D10: Car EMI | E10: EMI
B11: 46204 | C11: 189000 | D11: investments | E11: Savings-Optional
B12: 46204 | C12: 2500 | D12: maid | E12: Utilities
B13: 46204 | C13: 13211 | D13: phone EMI | E13: EMI
B14: 46204 | C14: 10000 | D14: Meera | E14: Personal
B15: 46204 | C15: 353 | D15: eat out | E15: Food
B16: 46209 | C16: =510+560+15+10 -> 1095 | D16: cbe travel | E16: Travel
B17: 46209 | C17: =80+90+148+110 -> 428 | D17: cbe food | E17: Travel
B18: 46209 | C18: 1020 | D18: cbe stay | E18: Travel
B19: 46205 | C19: 34971 | D19: HDFC cashback | E19: Savings-Mandatory
B20: 46206 | C20: 460 | D20: umbrella | E20: Personal | M20: Expenses | O20: Excluding Optional investment | S20: Income
B21: 46206 | C21: 753 | D21: eat out | E21: Food | M21: Actual | N21: =O26 -> 315634 | O21: =SUM(O28:O40,O42,O43) -> 126634 | S21: Actual | T21: =U26 -> 319000 | U21: =IFERROR(__xludf.DUMMYFUNCTION("SPARKLINE(T21,{""charttype"",""bar"";""max"",max(T21);""color1"",""#334960""})"),"")
B22: 46208 | C22: 1427 | D22: Groceries | E22: Groceries | M22: Living expense | N22: =SUM(O28:O37,O39,O42,O43) -> 42852
B23: 46208 | C23: 8839 | D23: bag n fryer | E23: Home | M23: Surplus | O23: =T21-N21 -> 3366
B24: 46211 | C24: 506 | D24: eat out | E24: Food | M24: Expenses | S24: Income
B25: 46213 | C25: 942 | D25: eat out | E25: Food | O25: Actual | U25: Actual
B26: 46215 | C26: 610 | D26: Eat out | E26: Food | M26: Totals | O26: =SUM(O27:P117) -> 315634 | S26: Totals | U26: =SUM(U27:U44) -> 319000
B27: 46215 | C27: =270+120+200+100 -> 690 | D27: veggies | E27: Groceries | O27: =IF(ISBLANK($B29), "", SUMIF('07-26'!$E:$E,$B29,'07-26'!$C:$C)) -> 0 | U27: =IF(ISBLANK($H27), "", SUMIF('07-26'!$J:$J,$H27,'07-26'!$H:$H))
B28: 46214 | C28: 175 | D28: Badminton | E28: Personal | M28: Food | O28: =IF(ISBLANK($M28), "", SUMIF('07-26'!$E:$E,$M28,'07-26'!$C:$C)) -> 4570 | S28: Savings | U28: =IF(ISBLANK($S28), "", SUMIF('07-26'!$J:$J,$S28,'07-26'!$H:$H)) -> 0
B29: 46215 | C29: 2000 | D29: Glanzy petrol | E29: Transportation | M29: Gifts | O29: =IF(ISBLANK($M29), "", SUMIF('07-26'!$E:$E,$M29,'07-26'!$C:$C)) -> 0 | S29: Paycheck | U29: =IF(ISBLANK($S29), "", SUMIF('07-26'!$J:$J,$S29,'07-26'!$H:$H)) -> 319000
B30: 46213 | C30: 3083 | D30: shankars | E30: Groceries | M30: Health/medical | O30: =IF(ISBLANK($M30), "", SUMIF('07-26'!$E:$E,$M30,'07-26'!$C:$C)) -> 0 | S30: Bonus | U30: =IF(ISBLANK($S30), "", SUMIF('07-26'!$J:$J,$S30,'07-26'!$H:$H)) -> 0
B31: 46218 | C31: 255 | D31: eggs | E31: Groceries | M31: Home | O31: =IF(ISBLANK($M31), "", SUMIF('07-26'!$E:$E,$M31,'07-26'!$C:$C)) -> 8839 | S31: Interest | U31: =IF(ISBLANK($S31), "", SUMIF('07-26'!$J:$J,$S31,'07-26'!$H:$H)) -> 0
B32: 46218 | C32: =919+487 -> 1406 | D32: eat out | E32: Food | M32: Transportation | O32: =IF(ISBLANK($M32), "", SUMIF('07-26'!$E:$E,$M32,'07-26'!$C:$C)) -> 2070 | S32: Other | U32: =IF(ISBLANK($S32), "", SUMIF('07-26'!$J:$J,$S32,'07-26'!$H:$H)) -> 0
B33: 46218 | C33: 1500 | D33: massage | E33: Personal | M33: Personal | O33: =IF(ISBLANK($M33), "", SUMIF('07-26'!$E:$E,$M33,'07-26'!$C:$C)) -> 12565 | S33: Custom category | U33: =IF(ISBLANK($S33), "", SUMIF('07-26'!$J:$J,$S33,'07-26'!$H:$H)) -> 0
B34: 46219 | C34: 3237 | D34: Tax | E34: Utilities | M34: Groceries | O34: =IF(ISBLANK($M34), "", SUMIF('07-26'!$E:$E,$M34,'07-26'!$C:$C)) -> 5455 | V34: =IF(ISBLANK($H34), "", SUMIF('07-26'!$J:$J,$H34,'07-26'!$H:$H)) | W34: =IF(ISBLANK($H34), "", V34-U34)
B35: 46219 | C35: 430 | D35: footwear | E35: Personal | M35: Utilities | O35: =IF(ISBLANK($M35), "", SUMIF('07-26'!$E:$E,$M35,'07-26'!$C:$C)) -> 6531 | V35: =IF(ISBLANK($H35), "", SUMIF('07-26'!$J:$J,$H35,'07-26'!$H:$H)) | W35: =IF(ISBLANK($H35), "", V35-U35)
B36: 46221 | C36: 70 | D36: auto service | E36: Transportation | M36: Travel | O36: =IF(ISBLANK($M36), "", SUMIF('07-26'!$E:$E,$M36,'07-26'!$C:$C)) -> 2543 | V36: =IF(ISBLANK($H36), "", SUMIF('07-26'!$J:$J,$H36,'07-26'!$H:$H)) | W36: =IF(ISBLANK($H36), "", V36-U36)
B37: 46217 | C37: 0 | E37: Food | M37: Child expenses | O37: =IF(ISBLANK($M37), "", SUMIF('07-26'!$E:$E,$M37,'07-26'!$C:$C)) -> 0 | V37: =IF(ISBLANK($H37), "", SUMIF('07-26'!$J:$J,$H37,'07-26'!$H:$H)) | W37: =IF(ISBLANK($H37), "", V37-U37)
B38: 46217 | C38: 0 | E38: Groceries | M38: EMI | O38: =IF(ISBLANK($M38), "", SUMIF('07-26'!$E:$E,$M38,'07-26'!$C:$C)) -> 22811 | V38: =IF(ISBLANK($H38), "", SUMIF('07-26'!$J:$J,$H38,'07-26'!$H:$H)) | W38: =IF(ISBLANK($H38), "", V38-U38)
B39: 46219 | C39: 0 | E39: Home | M39: Entertainment | O39: =IF(ISBLANK($M39), "", SUMIF('07-26'!$E:$E,$M39,'07-26'!$C:$C)) -> 279 | V39: =IF(ISBLANK($H39), "", SUMIF('07-26'!$J:$J,$H39,'07-26'!$H:$H)) | W39: =IF(ISBLANK($H39), "", V39-U39)
B40: 46225 | C40: 0 | E40: Travel | M40: Savings-Mandatory | O40: =IF(ISBLANK($M40), "", SUMIF('07-26'!$E:$E,$M40,'07-26'!$C:$C)) -> 60971 | V40: =IF(ISBLANK($H40), "", SUMIF('07-26'!$J:$J,$H40,'07-26'!$H:$H)) | W40: =IF(ISBLANK($H40), "", V40-U40)
...

Sheet 06-26
B1: Change or add categories by updating the Expenses and Income tables in the SumJuny sheet.
B2: Expenses | G2: Income
M3: Monthly Budget
B4: Date | C4: Amount | D4: Description | E4: Category | G4: Date | H4: Amount | I4: Description | J4: Category
B5: 46174 | C5: 794 | D5: Broadband & TV | E5: Utilities | G5: 46174 | H5: 529000 | I5: Salary | J5: Paycheck
B6: 46174 | C6: 10000 | D6: PO | E6: Savings-Mandatory
B7: 46174 | C7: 16000 | D7: RD | E7: Savings-Mandatory
B8: 46174 | C8: 279 | D8: OTT | E8: Entertainment
B9: 46174 | C9: =609+12000+630+3900 -> 17139 | D9: Maintenance | E9: Utilities
B10: 46174 | C10: 9600 | D10: Car EMI | E10: EMI
B11: 46174 | C11: 265000 | D11: investments | E11: Savings-Optional
B12: 46174 | C12: 2500 | D12: maid | E12: Utilities
B13: 46174 | C13: 13683 | D13: phone EMI | E13: EMI
B14: 46174 | C14: 520 | D14: eat out | E14: Food
B15: 46174 | C15: =290 -> 290 | D15: egbana | E15: Groceries
B16: 46175 | C16: 738 | D16: welmart | E16: Groceries
B17: 46175 | C17: 21514 | D17: school fees | E17: Child expenses
B18: 46176 | C18: 2364 | D18: amz shopping | E18: Personal
B19: 46180 | C19: 400 | D19: egbana | E19: Groceries
B20: 46180 | C20: 540 | D20: veggies | E20: Groceries | M20: Expenses | O20: Excluding Optional investment | S20: Income
B21: 46177 | C21: 260 | D21: eat out | E21: Food | M21: Actual | N21: =O26 -> 407714 | O21: =SUM(O28:O40,O42,O43) -> 142714 | S21: Actual | T21: =U26 -> 529000 | U21: =IFERROR(__xludf.DUMMYFUNCTION("SPARKLINE(T21,{""charttype"",""bar"";""max"",max(T21);""color1"",""#334960""})"),"")
B22: 46180 | C22: 1970 | D22: Shankars stores | E22: Groceries | M22: Living expense | N22: =SUM(O28:O37,O39,O42,O43) -> 93431
B23: 46181 | C23: =510+560+6+15+9+16 -> 1116 | D23: cbe travel | E23: Travel | M23: Surplus | O23: =T21-N21 -> 121286
B24: 46181 | C24: =80+275+20+148+10+80+80+30 -> 723 | D24: cbe food | E24: Travel | M24: Expenses | S24: Income
B25: 46181 | C25: 900 | D25: cbe stay | E25: Travel | O25: Actual | U25: Actual
B26: 46179 | C26: =30+100 -> 130 | D26: Print photostat meera | E26: Personal | M26: Totals | O26: =SUM(O27:P81) -> 407714 | S26: Totals | U26: =SUM(U27:U44) -> 529000
B27: 46179 | C27: 260 | D27: eat out | E27: Food | O27: =IF(ISBLANK($B29), "", SUMIF('06-26'!$E:$E,$B29,'06-26'!$C:$C)) -> 0 | U27: =IF(ISBLANK($H27), "", SUMIF('06-26'!$J:$J,$H27,'06-26'!$H:$H))
B28: 46179 | C28: 650 | D28: Tubes | E28: Home | M28: Food | O28: =IF(ISBLANK($M28), "", SUMIF('06-26'!$E:$E,$M28,'06-26'!$C:$C)) -> 3607 | S28: Savings | U28: =IF(ISBLANK($S28), "", SUMIF('06-26'!$J:$J,$S28,'06-26'!$H:$H)) -> 0
B29: 46188 | C29: =609+560+10+16+9 -> 1204 | D29: cbe travel | E29: Travel | M29: Gifts | O29: =IF(ISBLANK($M29), "", SUMIF('06-26'!$E:$E,$M29,'06-26'!$C:$C)) -> 0 | S29: Paycheck | U29: =IF(ISBLANK($S29), "", SUMIF('06-26'!$J:$J,$S29,'06-26'!$H:$H)) -> 529000
B30: 46188 | C30: =80+15+168+95+30 -> 388 | D30: cbe food | E30: Travel | M30: Health/medical | O30: =IF(ISBLANK($M30), "", SUMIF('06-26'!$E:$E,$M30,'06-26'!$C:$C)) -> 939 | S30: Bonus | U30: =IF(ISBLANK($S30), "", SUMIF('06-26'!$J:$J,$S30,'06-26'!$H:$H)) -> 0
B31: 46188 | C31: 1020 | D31: cbe stay | E31: Travel | M31: Home | O31: =IF(ISBLANK($M31), "", SUMIF('06-26'!$E:$E,$M31,'06-26'!$C:$C)) -> 2567 | S31: Interest | U31: =IF(ISBLANK($S31), "", SUMIF('06-26'!$J:$J,$S31,'06-26'!$H:$H)) -> 0
B32: 46184 | C32: 747 | D32: Janitorial | E32: Home | M32: Transportation | O32: =IF(ISBLANK($M32), "", SUMIF('06-26'!$E:$E,$M32,'06-26'!$C:$C)) -> 0 | S32: Other | U32: =IF(ISBLANK($S32), "", SUMIF('06-26'!$J:$J,$S32,'06-26'!$H:$H)) -> 0
B33: 46184 | C33: 323 | D33: egbana | E33: Groceries | M33: Personal | O33: =IF(ISBLANK($M33), "", SUMIF('06-26'!$E:$E,$M33,'06-26'!$C:$C)) -> 4069 | S33: Custom category | U33: =IF(ISBLANK($S33), "", SUMIF('06-26'!$J:$J,$S33,'06-26'!$H:$H)) -> 0
B34: 46185 | C34: 939 | D34: amma meds | E34: Health/medical | M34: Groceries | O34: =IF(ISBLANK($M34), "", SUMIF('06-26'!$E:$E,$M34,'06-26'!$C:$C)) -> 9140 | V34: =IF(ISBLANK($H34), "", SUMIF('06-26'!$J:$J,$H34,'06-26'!$H:$H)) | W34: =IF(ISBLANK($H34), "", V34-U34)
B35: 46186 | C35: 660 | D35: biriyani | E35: Food | M35: Utilities | O35: =IF(ISBLANK($M35), "", SUMIF('06-26'!$E:$E,$M35,'06-26'!$C:$C)) -> 23196 | V35: =IF(ISBLANK($H35), "", SUMIF('06-26'!$J:$J,$H35,'06-26'!$H:$H)) | W35: =IF(ISBLANK($H35), "", V35-U35)
B36: 46186 | C36: 1754 | D36: dry fruits | E36: Groceries | M36: Travel | O36: =IF(ISBLANK($M36), "", SUMIF('06-26'!$E:$E,$M36,'06-26'!$C:$C)) -> 7859 | V36: =IF(ISBLANK($H36), "", SUMIF('06-26'!$J:$J,$H36,'06-26'!$H:$H)) | W36: =IF(ISBLANK($H36), "", V36-U36)
B37: 46187 | C37: =250+170+40+50 -> 510 | D37: eat out | E37: Food | M37: Child expenses | O37: =IF(ISBLANK($M37), "", SUMIF('06-26'!$E:$E,$M37,'06-26'!$C:$C)) -> 21514 | V37: =IF(ISBLANK($H37), "", SUMIF('06-26'!$J:$J,$H37,'06-26'!$H:$H)) | W37: =IF(ISBLANK($H37), "", V37-U37)
B38: 46187 | C38: 350 | D38: egbana | E38: Groceries | M38: EMI | O38: =IF(ISBLANK($M38), "", SUMIF('06-26'!$E:$E,$M38,'06-26'!$C:$C)) -> 23283 | V38: =IF(ISBLANK($H38), "", SUMIF('06-26'!$J:$J,$H38,'06-26'!$H:$H)) | W38: =IF(ISBLANK($H38), "", V38-U38)
B39: 46189 | C39: 1170 | D39: washing machine repair | E39: Home | M39: Entertainment | O39: =IF(ISBLANK($M39), "", SUMIF('06-26'!$E:$E,$M39,'06-26'!$C:$C)) -> 279 | V39: =IF(ISBLANK($H39), "", SUMIF('06-26'!$J:$J,$H39,'06-26'!$H:$H)) | W39: =IF(ISBLANK($H39), "", V39-U39)
B40: 46195 | C40: =510+560+10+10 -> 1090 | D40: cbe travel | E40: Travel | M40: Savings-Mandatory | O40: =IF(ISBLANK($M40), "", SUMIF('06-26'!$E:$E,$M40,'06-26'!$C:$C)) -> 26000 | V40: =IF(ISBLANK($H40), "", SUMIF('06-26'!$J:$J,$H40,'06-26'!$H:$H)) | W40: =IF(ISBLANK($H40), "", V40-U40)
...

Sheet 05-26
B1: Change or add categories by updating the Expenses and Income tables in the SumMayy sheet.
B2: Expenses | G2: Income
M3: Monthly Budget
B4: Date | C4: Amount | D4: Description | E4: Category | G4: Date | H4: Amount | I4: Description | J4: Category
B5: 46143 | C5: 794 | D5: Broadband & TV | E5: Utilities | G5: 46143 | H5: 267000 | I5: Salary | J5: Paycheck
B6: 46143 | C6: 10000 | D6: PO | E6: Savings-Mandatory
B7: 46143 | C7: 16000 | D7: RD | E7: Savings-Mandatory
B8: 46143 | C8: 279 | D8: OTT | E8: Entertainment
B9: 46143 | C9: 609 | D9: Maintenance | E9: Utilities
B10: 46143 | C10: 9600 | D10: Car EMI | E10: EMI
B11: 46162 | C11: 166000 | D11: investments | E11: Savings-Optional
B12: 46143 | C12: 2500 | D12: maid | E12: Utilities
B13: 46143 | C13: 13683 | D13: phone EMI | E13: EMI
B14: 46143 | C14: 520 | D14: eat out | E14: Food
B15: 46143 | C15: =288+56 -> 344 | D15: egbana | E15: Groceries
B16: 46144 | C16: =2124+169+245 -> 2538 | D16: dry fruits | E16: Groceries
B17: 46144 | C17: 486 | D17: eat out | E17: Food
B18: 46145 | C18: 290 | D18: veggies | E18: Groceries
B19: 46145 | C19: 186 | D19: welmart | E19: Groceries
B20: 46147 | C20: 2250 | D20: blood test | E20: Health/medical | M20: Expenses | O20: Excluding Optional investment | S20: Income
B21: 46149 | C21: 337 | D21: eat out | E21: Food | M21: Actual | N21: =O26 -> 250829 | O21: =SUM(O28:O40,O42,O43) -> 84829 | S21: Actual | T21: =U26 -> 267000 | U21: =IFERROR(__xludf.DUMMYFUNCTION("SPARKLINE(T21,{""charttype"",""bar"";""max"",max(T21);""color1"",""#334960""})"),"")
B22: 46151 | C22: 125 | D22: ice cream | E22: Groceries | M22: Living expense | N22: =SUM(O28:O37,O39,O42,O43) -> 35546
B23: 46152 | C23: 765 | D23: eat out | E23: Food | M23: Surplus | O23: =T21-N21 -> 16171
B24: 46153 | C24: 1839 | D24: welmart | E24: Groceries | M24: Expenses | S24: Income
B25: 46156 | C25: 449 | D25: egbana | E25: Groceries | O25: Actual | U25: Actual
B26: 46156 | C26: 1812 | D26: home shopping | E26: Home | M26: Totals | O26: =SUM(O27:P81) -> 250829 | S26: Totals | U26: =SUM(U27:U44) -> 267000
B27: 46157 | C27: 375 | D27: eat out | E27: Food | O27: =IF(ISBLANK($B29), "", SUMIF('05-26'!$E:$E,$B29,'05-26'!$C:$C)) -> 0 | U27: =IF(ISBLANK($H27), "", SUMIF('05-26'!$J:$J,$H27,'05-26'!$H:$H))
B28: 46158 | C28: 2381 | D28: shankars stores | E28: Groceries | M28: Food | O28: =IF(ISBLANK($M28), "", SUMIF('05-26'!$E:$E,$M28,'05-26'!$C:$C)) -> 4337 | S28: Savings | U28: =IF(ISBLANK($S28), "", SUMIF('05-26'!$J:$J,$S28,'05-26'!$H:$H)) -> 0
B29: 46159 | C29: 90 | D29: badminton | E29: Personal | M29: Gifts | O29: =IF(ISBLANK($M29), "", SUMIF('05-26'!$E:$E,$M29,'05-26'!$C:$C)) -> 0 | S29: Paycheck | U29: =IF(ISBLANK($S29), "", SUMIF('05-26'!$J:$J,$S29,'05-26'!$H:$H)) -> 267000
B30: 46159 | C30: 660 | D30: veggies | E30: Groceries | M30: Health/medical | O30: =IF(ISBLANK($M30), "", SUMIF('05-26'!$E:$E,$M30,'05-26'!$C:$C)) -> 3462 | S30: Bonus | U30: =IF(ISBLANK($S30), "", SUMIF('05-26'!$J:$J,$S30,'05-26'!$H:$H)) -> 0
B31: 46159 | C31: 593 | D31: home stuff | E31: Home | M31: Home | O31: =IF(ISBLANK($M31), "", SUMIF('05-26'!$E:$E,$M31,'05-26'!$C:$C)) -> 2515 | S31: Interest | U31: =IF(ISBLANK($S31), "", SUMIF('05-26'!$J:$J,$S31,'05-26'!$H:$H)) -> 0
B32: 46161 | C32: 2681 | D32: dry fruits | E32: Groceries | M32: Transportation | O32: =IF(ISBLANK($M32), "", SUMIF('05-26'!$E:$E,$M32,'05-26'!$C:$C)) -> 291 | S32: Other | U32: =IF(ISBLANK($S32), "", SUMIF('05-26'!$J:$J,$S32,'05-26'!$H:$H)) -> 0
B33: 46163 | C33: 440 | D33: meds | E33: Health/medical | M33: Personal | O33: =IF(ISBLANK($M33), "", SUMIF('05-26'!$E:$E,$M33,'05-26'!$C:$C)) -> 5451 | S33: Custom category | U33: =IF(ISBLANK($S33), "", SUMIF('05-26'!$J:$J,$S33,'05-26'!$H:$H)) -> 0
B34: 46163 | C34: =360+150 -> 510 | D34: egbana | E34: Groceries | M34: Groceries | O34: =IF(ISBLANK($M34), "", SUMIF('05-26'!$E:$E,$M34,'05-26'!$C:$C)) -> 15308 | V34: =IF(ISBLANK($H34), "", SUMIF('05-26'!$J:$J,$H34,'05-26'!$H:$H)) | W34: =IF(ISBLANK($H34), "", V34-U34)
B35: 46164 | C35: 110 | D35: haircut | E35: Personal | M35: Utilities | O35: =IF(ISBLANK($M35), "", SUMIF('05-26'!$E:$E,$M35,'05-26'!$C:$C)) -> 3903 | V35: =IF(ISBLANK($H35), "", SUMIF('05-26'!$J:$J,$H35,'05-26'!$H:$H)) | W35: =IF(ISBLANK($H35), "", V35-U35)
B36: 46164 | C36: 346 | D36: meds | E36: Health/medical | M36: Travel | O36: =IF(ISBLANK($M36), "", SUMIF('05-26'!$E:$E,$M36,'05-26'!$C:$C)) -> 0 | V36: =IF(ISBLANK($H36), "", SUMIF('05-26'!$J:$J,$H36,'05-26'!$H:$H)) | W36: =IF(ISBLANK($H36), "", V36-U36)
B37: 46164 | C37: 645 | D37: eat out | E37: Food | M37: Child expenses | O37: =IF(ISBLANK($M37), "", SUMIF('05-26'!$E:$E,$M37,'05-26'!$C:$C)) -> 0 | V37: =IF(ISBLANK($H37), "", SUMIF('05-26'!$J:$J,$H37,'05-26'!$H:$H)) | W37: =IF(ISBLANK($H37), "", V37-U37)
B38: 46164 | C38: 291 | D38: petrol | E38: Transportation | M38: EMI | O38: =IF(ISBLANK($M38), "", SUMIF('05-26'!$E:$E,$M38,'05-26'!$C:$C)) -> 23283 | V38: =IF(ISBLANK($H38), "", SUMIF('05-26'!$J:$J,$H38,'05-26'!$H:$H)) | W38: =IF(ISBLANK($H38), "", V38-U38)
B39: 46162 | C39: =160+300 -> 460 | D39: veggies | E39: Groceries | M39: Entertainment | O39: =IF(ISBLANK($M39), "", SUMIF('05-26'!$E:$E,$M39,'05-26'!$C:$C)) -> 279 | V39: =IF(ISBLANK($H39), "", SUMIF('05-26'!$J:$J,$H39,'05-26'!$H:$H)) | W39: =IF(ISBLANK($H39), "", V39-U39)
B40: 46163 | C40: 1353 | D40: welmart | E40: Groceries | M40: Savings-Mandatory | O40: =IF(ISBLANK($M40), "", SUMIF('05-26'!$E:$E,$M40,'05-26'!$C:$C)) -> 26000 | V40: =IF(ISBLANK($H40), "", SUMIF('05-26'!$J:$J,$H40,'05-26'!$H:$H)) | W40: =IF(ISBLANK($H40), "", V40-U40)
...

Sheet 04-26
B1: Change or add categories by updating the Expenses and Income tables in the SumApry sheet.
B2: Expenses | G2: Income
M3: Monthly Budget
B4: Date | C4: Amount | D4: Description | E4: Category | G4: Date | H4: Amount | I4: Description | J4: Category
B5: 46113 | C5: 794 | D5: Broadband & TV | E5: Utilities | G5: 46113 | H5: 239000 | I5: Salary | J5: Paycheck
B6: 46113 | C6: 10000 | D6: PO | E6: Savings-Mandatory
B7: 46113 | C7: 16000 | D7: RD | E7: Savings-Mandatory
B8: 46113 | C8: 279 | D8: OTT | E8: Entertainment
B9: 46113 | C9: 15229 | D9: Maintenance | E9: Utilities
B10: 46113 | C10: 9600 | D10: Car EMI | E10: EMI
B11: 46132 | C11: 150000 | D11: investments SSKY | E11: Savings-Optional
B12: 46113 | C12: 2500 | D12: maid | E12: Utilities
B13: 46113 | C13: 13683 | D13: phone EMI | E13: EMI
B14: 46113 | C14: 3207 | D14: clothes | E14: Personal
B15: 46113 | C15: 170 | D15: sundry | E15: Personal
B16: 46113 | C16: 2000 | D16: glanzy petrol | E16: Transportation
B17: 46118 | C17: 892 | D17: cbe travel | E17: Travel
... B19: 46118 | C19: 930 | D19: cbe stay | E19: Travel
B20: 46116 | C20: 115 | D20: groceries | E20: Groceries | M20: Expenses | O20: Excluding Optional investment | S20: Income
B21: 46116 | C21: 570 | D21: gut string | E21: Personal | M21: Actual | N21: =O26 -> 253742 | O21: =SUM(O28:O40,O42,O43) -> 103742 | S21: Actual | T21: =U26 -> 239000 | U21: =IFERROR(__xludf.DUMMYFUNCTION("SPARKLINE(T21,{""charttype"",""bar"";""max"",max(T21);""color1"",""#334960""})"),"")
B22: 46116 | C22: 450 | D22: ice cream | E22: Food | M22: Living expense | N22: =SUM(O28:O37,O39,O42,O43) -> 54459
B23: 46116 | C23: 90 | D23: badminton | E23: Personal | M23: Surplus | O23: =T21-N21 -> -14742
B24: 46117 | C24: 525 | D24: eat out | E24: Food | M24: Expenses | S24: Income
B25: 46117 | C25: 380 | D25: Cricket | E25: Personal | O25: Actual | U25: Actual
B26: 46119 | C26: 1620 | D26: achus textbook s | E26: Child expenses | M26: Totals | O26: =SUM(O27:P81) -> 253742 | S26: Totals | U26: =SUM(U27:U44) -> 239000
B27: 46119 | C27: 74 | D27: banana | E27: Groceries | O27: =IF(ISBLANK($B29), "", SUMIF('04-26'!$E:$E,$B29,'04-26'!$C:$C)) -> 0 | U27: =IF(ISBLANK($H27), "", SUMIF('04-26'!$J:$J,$H27,'04-26'!$H:$H))
B28: 46123 | C28: 300 | D28: eat out | E28: Food | M28: Food | O28: =IF(ISBLANK($M28), "", SUMIF('04-26'!$E:$E,$M28,'04-26'!$C:$C)) -> 5149 | S28: Savings | U28: =IF(ISBLANK($S28), "", SUMIF('04-26'!$J:$J,$S28,'04-26'!$H:$H)) -> 0
B29: 46123 | C29: 1700 | D29: exhibition | E29: Home | M29: Gifts | O29: =IF(ISBLANK($M29), "", SUMIF('04-26'!$E:$E,$M29,'04-26'!$C:$C)) -> 0 | S29: Paycheck | U29: =IF(ISBLANK($S29), "", SUMIF('04-26'!$J:$J,$S29,'04-26'!$H:$H)) -> 239000
B30: 46124 | C30: 357 | D30: egbana | E30: Groceries | M30: Health/medical | O30: =IF(ISBLANK($M30), "", SUMIF('04-26'!$E:$E,$M30,'04-26'!$C:$C)) -> 0 | S30: Bonus | U30: =IF(ISBLANK($S30), "", SUMIF('04-26'!$J:$J,$S30,'04-26'!$H:$H)) -> 0
B31: 46124 | C31: 300 | D31: cricket | E31: Personal | M31: Home | O31: =IF(ISBLANK($M31), "", SUMIF('04-26'!$E:$E,$M31,'04-26'!$C:$C)) -> 1700 | S31: Interest | U31: =IF(ISBLANK($S31), "", SUMIF('04-26'!$J:$J,$S31,'04-26'!$H:$H)) -> 0
B32: 46124 | C32: 530 | D32: veggies | E32: Groceries | M32: Transportation | O32: =IF(ISBLANK($M32), "", SUMIF('04-26'!$E:$E,$M32,'04-26'!$C:$C)) -> 2000 | S32: Other | U32: =IF(ISBLANK($S32), "", SUMIF('04-26'!$J:$J,$S32,'04-26'!$H:$H)) -> 0
B33: 46126 | C33: 617 | D33: movies | E33: Entertainment | M33: Personal | O33: =IF(ISBLANK($M33), "", SUMIF('04-26'!$E:$E,$M33,'04-26'!$C:$C)) -> 4883 | S33: Custom category | U33: =IF(ISBLANK($S33), "", SUMIF('04-26'!$J:$J,$S33,'04-26'!$H:$H)) -> 0
B34: 46126 | C34: 505 | D34: rao groceries | E34: Groceries | M34: Groceries | O34: =IF(ISBLANK($M34), "", SUMIF('04-26'!$E:$E,$M34,'04-26'!$C:$C)) -> 8797 | V34: =IF(ISBLANK($H34), "", SUMIF('04-26'!$J:$J,$H34,'04-26'!$H:$H)) | W34: =IF(ISBLANK($H34), "", V34-U34)
B35: 46127 | C35: 110 | D35: haircut | E35: Personal | M35: Utilities | O35: =IF(ISBLANK($M35), "", SUMIF('04-26'!$E:$E,$M35,'04-26'!$C:$C)) -> 21964 | V35: =IF(ISBLANK($H35), "", SUMIF('04-26'!$J:$J,$H35,'04-26'!$H:$H)) | W35: =IF(ISBLANK($H35), "", V35-U35)
B36: 46129 | C36: 809 | D36: eat out | E36: Food | M36: Travel | O36: =IF(ISBLANK($M36), "", SUMIF('04-26'!$E:$E,$M36,'04-26'!$C:$C)) -> 2750 | V36: =IF(ISBLANK($H36), "", SUMIF('04-26'!$J:$J,$H36,'04-26'!$H:$H)) | W36: =IF(ISBLANK($H36), "", V36-U36)
B37: 46127 | C37: 5173 | D37: shankars | E37: Groceries | M37: Child expenses | O37: =IF(ISBLANK($M37), "", SUMIF('04-26'!$E:$E,$M37,'04-26'!$C:$C)) -> 6320 | V37: =IF(ISBLANK($H37), "", SUMIF('04-26'!$J:$J,$H37,'04-26'!$H:$H)) | W37: =IF(ISBLANK($H37), "", V37-U37)
B38: 46131 | C38: 28 | D38: milk | E38: Groceries | M38: EMI | O38: =IF(ISBLANK($M38), "", SUMIF('04-26'!$E:$E,$M38,'04-26'!$C:$C)) -> 23283 | V38: =IF(ISBLANK($H38), "", SUMIF('04-26'!$J:$J,$H38,'04-26'!$H:$H)) | W38: =IF(ISBLANK($H38), "", V38-U38)
B39: 46132 | C39: 415 | D39: veggies | E39: Groceries | M39: Entertainment | O39: =IF(ISBLANK($M39), "", SUMIF('04-26'!$E:$E,$M39,'04-26'!$C:$C)) -> 896 | V39: =IF(ISBLANK($H39), "", SUMIF('04-26'!$J:$J,$H39,'04-26'!$H:$H)) | W39: =IF(ISBLANK($H39), "", V39-U39)
B40: 46133 | C40: 777 | D40: eat out | E40: Food | M40: Savings-Mandatory | O40: =IF(ISBLANK($M40), "", SUMIF('04-26'!$E:$E,$M40,'04-26'!$C:$C)) -> 26000 | V40: =IF(ISBLANK($H40), "", SUMIF('04-26'!$J:$J,$H40,'04-26'!$H:$H)) | W40: =IF(ISBLANK($H40), "", V40-U40)
B41: 46134 | C41: 315 | D41: egbana | E41: Groceries | M41: Savings-Optional | O41: =IF(ISBLANK($M41), "", SUMIF('04-26'!$E:$E,$M41,'04-26'!$C:$C)) -> 150000 | V41: =IF(ISBLANK($H41), "", SUMIF('04-26'!$J:$J,$H41,'04-26'!$H:$H)) | W41: =IF(ISBLANK($H41), "", V41-U41)
...

Sheet Analysis

Sheet Jun 26 - Review
A3: Month-Year | B3: EMI | C3: Entertainment | D3: Experiences | E3: Food | F3: Gifts | G3: Groceries | H3: Health/medical | I3: Home | J3: Personal | K3: Savings-Mandatory | L3: Savings-Optional | M3: Transportation | N3: Utilities | O3: Travel
A4: 45748 | B4: 9600 | C4: 1783 | D4: 28302 | E4: 6811 | F4: 650 | G4: 7679 | H4: 234 | I4: 12560 | J4: 5006 | K4: 23500 | L4: 166000 | M4: 1400 | N4: 8001
A5: 45778 | B5: 9600 | C5: 2094 | E5: 1770 | G5: 8226 | H5: 771 | I5: 3897 | J5: 11154 | K5: 23500 | L5: 150000 | M5: 2297 | N5: 5703
A6: 45809 | B6: 9600 | C6: 499 | E6: 3829 | G6: 8953 | I6: 1148 | J6: 2832 | K6: 23500 | L6: 320000 | M6: 297 | N6: 13169 | O6: 14872
A7: 45839 | B7: 9600 | C7: 499 | E7: 5580 | F7: 408 | G7: 10116 | I7: 4856 | J7: 1990 | K7: 83166 | L7: 166000 | M7: 2635 | N7: 1171 | O7: 3906
A8: 45870 | B8: 9600 | C8: 499 | E8: 2601 | F8: 540 | G8: 9141 | I8: 3764 | J8: 3549 | K8: 23500 | L8: 196000 | M8: 2125 | N8: 2711 | O8: 3549
A9: 45901 | B9: 9600 | C9: 977 | E9: 4856 | G9: 12127 | H9: 26212 | J9: 8120 | K9: 37452 | L9: 86000 | M9: 320 | N9: 22874 | O9: 6499
